Workbook

Sheet Executive Dashboard
B2: AI Customer Support Ticket Intelligence Dashboard
B5: TOTAL TICKETS | D5: AVG RESOLUTION TIME (HRS) | F5: HIGH PRIORITY TICKETS | H5: OPEN TICKETS | J5: CLOSED TICKETS | L5: AVERAGE CSAT RATING
B6: =COUNTA('Cleaned Data'!A2:A8470) -> 8469 | D6: =ROUND(AVERAGE('Cleaned Data'!X2:X8470), 2) -> 61.01 | F6: =COUNTIF('Cleaned Data'!M2:M8470, "High") -> 2085 | H6: =COUNTIF('Cleaned Data'!K2:K8470, "Open") -> 2819 | J6: =COUNTIF('Cleaned Data'!K2:K8470, "Closed") -> 2769 | L6: =ROUND(AVERAGEIFS('Cleaned Data'!Q2:Q8470, 'Cleaned Data'!Q2:Q8470, ">=1"), 2) -> 2.99
B9: Ticket Distribution by Category & Priority
B10: Ticket Category | C10: High | D10: Medium | E10: Low | F10: Total
B11: Account | C11: =COUNTIFS('Cleaned Data'!$T$2:$T$8470, B11, 'Cleaned Data'!$M$2:$M$8470, "High") -> 46 | D11: =COUNTIFS('Cleaned Data'!$T$2:$T$8470, B11, 'Cleaned Data'!$M$2:$M$8470, "Medium") -> 52 | E11: =COUNTIFS('Cleaned Data'!$T$2:$T$8470, B11, 'Cleaned Data'!$M$2:$M$8470, "Low") -> 43 | F11: =SUM(C11:E11) -> 141
B12: Billing | C12: =COUNTIFS('Cleaned Data'!$T$2:$T$8470, B12, 'Cleaned Data'!$M$2:$M$8470, "High") -> 274 | D12: =COUNTIFS('Cleaned Data'!$T$2:$T$8470, B12, 'Cleaned Data'!$M$2:$M$8470, "Medium") -> 315 | E12: =COUNTIFS('Cleaned Data'!$T$2:$T$8470, B12, 'Cleaned Data'!$M$2:$M$8470, "Low") -> 292 | F12: =SUM(C12:E12) -> 881
B13: Login | C13: =COUNTIFS('Cleaned Data'!$T$2:$T$8470, B13, 'Cleaned Data'!$M$2:$M$8470, "High") -> 262 | D13: =COUNTIFS('Cleaned Data'!$T$2:$T$8470, B13, 'Cleaned Data'!$M$2:$M$8470, "Medium") -> 281 | E13: =COUNTIFS('Cleaned Data'!$T$2:$T$8470, B13, 'Cleaned Data'!$M$2:$M$8470, "Low") -> 270 | F13: =SUM(C13:E13) -> 813
B14: Refund | C14: =COUNTIFS('Cleaned Data'!$T$2:$T$8470, B14, 'Cleaned Data'!$M$2:$M$8470, "High") -> 168 | D14: =COUNTIFS('Cleaned Data'!$T$2:$T$8470, B14, 'Cleaned Data'!$M$2:$M$8470, "Medium") -> 179 | E14: =COUNTIFS('Cleaned Data'!$T$2:$T$8470, B14, 'Cleaned Data'!$M$2:$M$8470, "Low") -> 176 | F14: =SUM(C14:E14) -> 523
B15: Shipping | C15: =COUNTIFS('Cleaned Data'!$T$2:$T$8470, B15, 'Cleaned Data'!$M$2:$M$8470, "High") -> 267 | D15: =COUNTIFS('Cleaned Data'!$T$2:$T$8470, B15, 'Cleaned Data'!$M$2:$M$8470, "Medium") -> 267 | E15: =COUNTIFS('Cleaned Data'!$T$2:$T$8470, B15, 'Cleaned Data'!$M$2:$M$8470, "Low") -> 222 | F15: =SUM(C15:E15) -> 756
B16: Technical | C16: =COUNTIFS('Cleaned Data'!$T$2:$T$8470, B16, 'Cleaned Data'!$M$2:$M$8470, "High") -> 1068 | D16: =COUNTIFS('Cleaned Data'!$T$2:$T$8470, B16, 'Cleaned Data'!$M$2:$M$8470, "Medium") -> 1098 | E16: =COUNTIFS('Cleaned Data'!$T$2:$T$8470, B16, 'Cleaned Data'!$M$2:$M$8470, "Low") -> 1060 | F16: =SUM(C16:E16) -> 3226
B17: Total | C17: =SUM(C11:C16) -> 2085 | D17: =SUM(D11:D16) -> 2192 | E17: =SUM(E11:E16) -> 2063 | F17: =SUM(F11:F16) -> 6340
B19: Top 10 Support Agents Performance
B20: Support Agent | C20: Tickets Assigned | D20: Average CSAT | E20: Avg Resolution Time (hrs)
B21: Kevin Bacon | C21: =COUNTIF('Cleaned Data'!$U$2:$U$8470, B21) -> 623 | D21: =ROUND(AVERAGEIFS('Cleaned Data'!$Q$2:$Q$8470, 'Cleaned Data'!$U$2:$U$8470, B21, 'Cleaned Data'!$Q$2:$Q$8470, ">=1"), 2) -> 2.82 | E21: =ROUND(AVERAGEIF('Cleaned Data'!$U$2:$U$8470, B21, 'Cleaned Data'!$X$2:$X$8470), 2) -> 62.14
B22: Michael Scott | C22: =COUNTIF('Cleaned Data'!$U$2:$U$8470, B22) -> 586 | D22: =ROUND(AVERAGEIFS('Cleaned Data'!$Q$2:$Q$8470, 'Cleaned Data'!$U$2:$U$8470, B22, 'Cleaned Data'!$Q$2:$Q$8470, ">=1"), 2) -> 2.98 | E22: =ROUND(AVERAGEIF('Cleaned Data'!$U$2:$U$8470, B22, 'Cleaned Data'!$X$2:$X$8470), 2) -> 61.09
B23: Ian Malcolm | C23: =COUNTIF('Cleaned Data'!$U$2:$U$8470, B23) -> 582 | D23: =ROUND(AVERAGEIFS('Cleaned Data'!$Q$2:$Q$8470, 'Cleaned Data'!$U$2:$U$8470, B23, 'Cleaned Data'!$Q$2:$Q$8470, ">=1"), 2) -> 2.8 | E23: =ROUND(AVERAGEIF('Cleaned Data'!$U$2:$U$8470, B23, 'Cleaned Data'!$X$2:$X$8470), 2) -> 60.14
B24: Bob Johnson | C24: =COUNTIF('Cleaned Data'!$U$2:$U$8470, B24) -> 577 | D24: =ROUND(AVERAGEIFS('Cleaned Data'!$Q$2:$Q$8470, 'Cleaned Data'!$U$2:$U$8470, B24, 'Cleaned Data'!$Q$2:$Q$8470, ">=1"), 2) -> 3.1 | E24: =ROUND(AVERAGEIF('Cleaned Data'!$U$2:$U$8470, B24, 'Cleaned Data'!$X$2:$X$8470), 2) -> 64.92
B25: Hannah Abbott | C25: =COUNTIF('Cleaned Data'!$U$2:$U$8470, B25) -> 577 | D25: =ROUND(AVERAGEIFS('Cleaned Data'!$Q$2:$Q$8470, 'Cleaned Data'!$U$2:$U$8470, B25, 'Cleaned Data'!$Q$2:$Q$8470, ">=1"), 2) -> 3.11 | E25: =ROUND(AVERAGEIF('Cleaned Data'!$U$2:$U$8470, B25, 'Cleaned Data'!$X$2:$X$8470), 2) -> 63.71
B26: Laura Croft | C26: =COUNTIF('Cleaned Data'!$U$2:$U$8470, B26) -> 576 | D26: =ROUND(AVERAGEIFS('Cleaned Data'!$Q$2:$Q$8470, 'Cleaned Data'!$U$2:$U$8470, B26, 'Cleaned Data'!$Q$2:$Q$8470, ">=1"), 2) -> 2.84 | E26: =ROUND(AVERAGEIF('Cleaned Data'!$U$2:$U$8470, B26, 'Cleaned Data'!$X$2:$X$8470), 2) -> 61.96
B27: George Clark | C27: =COUNTIF('Cleaned Data'!$U$2:$U$8470, B27) -> 567 | D27: =ROUND(AVERAGEIFS('Cleaned Data'!$Q$2:$Q$8470, 'Cleaned Data'!$U$2:$U$8470, B27, 'Cleaned Data'!$Q$2:$Q$8470, ">=1"), 2) -> 2.94 | E27: =ROUND(AVERAGEIF('Cleaned Data'!$U$2:$U$8470, B27, 'Cleaned Data'!$X$2:$X$8470), 2) -> 57.27
B28: Fiona Gallagher | C28: =COUNTIF('Cleaned Data'!$U$2:$U$8470, B28) -> 567 | D28: =ROUND(AVERAGEIFS('Cleaned Data'!$Q$2:$Q$8470, 'Cleaned Data'!$U$2:$U$8470, B28, 'Cleaned Data'!$Q$2:$Q$8470, ">=1"), 2) -> 3.08 | E28: =ROUND(AVERAGEIF('Cleaned Data'!$U$2:$U$8470, B28, 'Cleaned Data'!$X$2:$X$8470), 2) -> 60.99
B29: Ethan Hunt | C29: =COUNTIF('Cleaned Data'!$U$2:$U$8470, B29) -> 565 | D29: =ROUND(AVERAGEIFS('Cleaned Data'!$Q$2:$Q$8470, 'Cleaned Data'!$U$2:$U$8470, B29, 'Cleaned Data'!$Q$2:$Q$8470, ">=1"), 2) -> 3.1 | E29: =ROUND(AVERAGEIF('Cleaned Data'!$U$2:$U$8470, B29, 'Cleaned Data'!$X$2:$X$8470), 2) -> 59.34
B30: Charlie Brown | C30: =COUNTIF('Cleaned Data'!$U$2:$U$8470, B30) -> 563 | D30: =ROUND(AVERAGEIFS('Cleaned Data'!$Q$2:$Q$8470, 'Cleaned Data'!$U$2:$U$8470, B30, 'Cleaned Data'!$Q$2:$Q$8470, ">=1"), 2) -> 3.04 | E30: =ROUND(AVERAGEIF('Cleaned Data'!$U$2:$U$8470, B30, 'Cleaned Data'!$X$2:$X$8470), 2) -> 59.09
B33: Monthly Ticket Volume Trends
B34: Month | C34: Tickets Logged
B35: 2021-12 | C35: =COUNTIF('Cleaned Data'!$Y$2:$Y$8470, B35) -> 3
B36: 2022-01 | C36: =COUNTIF('Cleaned Data'!$Y$2:$Y$8470, B36) -> 230
B37: 2022-02 | C37: =COUNTIF('Cleaned Data'!$Y$2:$Y$8470, B37) -> 232
B38: 2022-03 | C38: =COUNTIF('Cleaned Data'!$Y$2:$Y$8470, B38) -> 273
B39: 2022-04 | C39: =COUNTIF('Cleaned Data'!$Y$2:$Y$8470, B39) -> 229
B40: 2022-05 | C40: =COUNTIF('Cleaned Data'!$Y$2:$Y$8470, B40) -> 254
B41: 2022-06 | C41: =COUNTIF('Cleaned Data'!$Y$2:$Y$8470, B41) -> 231
B42: 2022-07 | C42: =COUNTIF('Cleaned Data'!$Y$2:$Y$8470, B42) -> 241
B43: 2022-08 | C43: =COUNTIF('Cleaned Data'!$Y$2:$Y$8470, B43) -> 240
B44: 2022-09 | C44: =COUNTIF('Cleaned Data'!$Y$2:$Y$8470, B44) -> 239
B45: 2022-10 | C45: =COUNTIF('Cleaned Data'!$Y$2:$Y$8470, B45) -> 246
B46: 2022-11 | C46: =COUNTIF('Cleaned Data'!$Y$2:$Y$8470, B46) -> 228
... B71: 2024-12 | C71: =COUNTIF('Cleaned Data'!$Y$2:$Y$8470, B71) -> 212

Sheet Cleaned Data
A1: Ticket_ID | B1: Customer_Name | C1: Customer_Email | D1: Customer_Age | E1: Customer_Gender | F1: Product_Purchased | G1: Date_of_Purchase | H1: Ticket_Type | I1: Ticket_Subject | J1: Ticket_Description | K1: Ticket_Status | L1: Resolution | M1: Ticket_Priority | N1: Ticket_Channel | O1: First_Response_Time | P1: Time_to_Resolution | Q1: Customer_Satisfaction_Rating | R1: Priority | S1: Status | T1: Ticket_Category | U1: Support_Agent | V1: Created_Date | W1: Resolved_Date | X1: Resolution_Time | Y1: Year_Month
A2: 1 | B2: Marisa Obrien | C2: carrollallison@example.com | D2: 32 | E2: Other | F2: GoPro Hero | G2: 2021-03-22 | H2: Technical issue | I2: Product setup | J2: I'm having an issue with the {product_purchased}. Please assist. Your billing zip code is: 71701. We appreciate that you have requested a website address. Please double check your email address. I've tried troubleshooting steps mentioned in the user manual, but the issue persists. | K2: Pending Customer Response | L2: Under Investigation | M2: Critical | N2: Social media | O2: 2023-06-01 12:15:36 | Q2: -1 | R2: High | S2: Pending Customer Response | T2: Billing | U2: Kevin Bacon | V2: 44971.892 | Y2: 2023-02
A3: 2 | B3: Jessica Rios | C3: clarkeashley@example.com | D3: 42 | E3: Female | F3: LG Smart TV | G3: 2021-05-22 | H3: Technical issue | I3: Peripheral compatibility | J3: I'm having an issue with the {product_purchased}. Please assist. If you need to change an existing product. I'm having an issue with the {product_purchased}. Please assist. If The issue I'm facing is intermittent. Sometimes it works fine, but other times it acts up unexpectedly. | K3: Pending Customer Response | L3: Under Investigation | M3: Critical | N3: Chat | O3: 2023-06-01 16:45:38 | Q3: -1 | R3: High | S3: Pending Customer Response | T3: Technical | U3: Bob Johnson | V3: 45602.803 | Y3: 2024-11
A4: 3 | B4: Christopher Robbins | C4: gonzalestracy@example.com | D4: 48 | E4: Other | F4: Dell XPS | G4: 2020-07-14 | H4: Technical issue | I4: Network problem | J4: I'm facing a problem with my {product_purchased}. The {product_purchased} is not turning on. It was working fine until yesterday, but now it doesn't respond. 1.8.3 I really I'm using the original charger that came with my {product_purchased}, but it's not charging properly. | K4: Closed | L4: Case maybe show recently my computer follow. | M4: Low | N4: Social media | O4: 2023-06-01 11:14:38 | P4: 2023-06-01 18:05:38 | Q4: 3 | R4: Low | S4: Closed | T4: Billing | U4: Alice Smith | V4: 45363.304 | W4: 2024-03-12 22:19:50.846893311 | X4: 15.03 | Y4: 2024-03
A5: 4 | B5: Christina Dillon | C5: bradleyolson@example.org | D5: 27 | E5: Female | F5: Microsoft Office | G5: 2020-11-13 | H5: Billing inquiry | I5: Account access | J5: I'm having an issue with the {product_purchased}. Please assist. If you have a problem you're interested in and I'd love to see this happen, please check out the Feedback. I've already contacted customer support multiple times, but the issue remains unresolved. | K5: Closed | L5: Try capital clearly never color toward story. | M5: Low | N5: Social media | O5: 2023-06-01 07:29:40 | P5: 2023-06-01 01:57:40 | Q5: 3 | R5: Low | S5: Closed | T5: Login | U5: Laura Croft | V5: 45217.302 | W5: 2023-10-20 22:59:05.872913361 | X5: 63.74 | Y5: 2023-10
A6: 5 | B6: Alexander Carroll | C6: bradleymark@example.com | D6: 67 | E6: Female | F6: Autodesk AutoCAD | G6: 2020-02-04 | H6: Billing inquiry | I6: Data loss | J6: I'm having an issue with the {product_purchased}. Please assist. Note: The seller is not responsible for any damages arising out of the delivery of the battleground game. Please have the game in good condition and shipped to you I've noticed a sudden decrease in battery life on my {product_purchased}. It used to last much longer. | K6: Closed | L6: West decision evidence bit. | M6: Low | N6: Email | O6: 2023-06-01 00:12:42 | P6: 2023-06-01 19:53:42 | Q6: 1 | R6: Low | S6: Closed | T6: Shipping | U6: Ethan Hunt | V6: 44732.611 | W6: 2022-06-21 00:32:23.534978151 | X6: 9.87 | Y6: 2022-06
A7: 6 | B7: Rebecca Fleming | C7: sheenasmith@example.com | D7: 53 | E7: Male | F7: Microsoft Office | G7: 2020-07-28 | H7: Cancellation request | I7: Payment issue | J7: I'm facing a problem with my {product_purchased}. The {product_purchased} is not turning on. It was working fine until yesterday, but now it doesn't respond. To remove the new {product_purch I've checked for any available software updates for my {product_purchased}, but there are none. | K7: Open | L7: Under Investigation | M7: Low | N7: Social media | Q7: -1 | R7: Low | S7: Open | T7: Billing | U7: Diana Prince | V7: 44732.585 | Y7: 2022-06
A8: 7 | B8: Jacqueline Wright | C8: donaldkeith@example.org | D8: 24 | E8: Other | F8: Microsoft Surface | G8: 2020-02-23 | H8: Product inquiry | I8: Refund request | J8: I'm unable to access my {product_purchased} account. It keeps displaying an 'Invalid Credentials' error, even though I'm using the correct login information. How can I regain access to my account? Solution 1 I'm unable to find the option to perform the desired action in the {product_purchased}. Could you please guide me through the steps? | K8: Open | L8: Under Investigation | M8: Critical | N8: Social media | Q8: -1 | R8: High | S8: Open | T8: Refund | U8: Diana Prince | V8: 44625.372 | Y8: 2022-03
A9: 8 | B9: Denise Lee | C9: joelwilliams@example.com | D9: 23 | E9: Male | F9: Philips Hue Lights | G9: 2020-08-09 | H9: Refund request | I9: Battery life | J9: I'm having an issue with the {product_purchased}. Please assist. (Thanks) I will contact all my suppliers and confirm. Please try and find out whether their inventory is currently stocked, or any other reason. I am I've performed a factory reset on my {product_purchased}, hoping it would resolve the problem, but it didn't help. | K9: Open | L9: Under Investigation | M9: Critical | N9: Social media | Q9: -1 | R9: High | S9: Open | T9: Login | U9: Charlie Brown | V9: 45510.234 | Y9: 2024-08
A10: 9 | B10: Nicolas Wilson | C10: joshua24@example.com | D10: 60 | E10: Other | F10: Fitbit Versa Smartwatch | G10: 2020-07-16 | H10: Technical issue | I10: Installation support | J10: I'm having an issue with the {product_purchased}. Please assist. Thank you. {product_purchased} is not the exact type you might prefer, they use the exact same method for different uses. Please help I've recently updated the firmware of my {product_purchased}, and the issue started happening afterward. Could it be related to the update? | K10: Pending Customer Response | L10: Under Investigation | M10: Low | N10: Social media | O10: 2023-06-01 10:32:47 | Q10: -1 | R10: Low | S10: Pending Customer Response | T10: Technical | U10: Laura Croft | V10: 45219.992 | Y10: 2023-10
A11: 10 | B11: William Dawson | C11: clopez@example.com | D11: 27 | E11: Male | F11: Dyson Vacuum Cleaner | G11: 2020-03-06 | H11: Refund request | I11: Payment issue | J11: My {product_purchased} is making strange noises and not functioning properly. I suspect there might be a hardware issue. Can you please help me with this? } If we can, please send a "request" to dav The issue I'm facing is intermittent. Sometimes it works fine, but other times it acts up unexpectedly. | K11: Pending Customer Response | L11: Under Investigation | M11: Critical | N11: Phone | O11: 2023-06-01 09:25:48 | Q11: -1 | R11: High | S11: Pending Customer Response | T11: Billing | U11: Bob Johnson | V11: 45337.11 | Y11: 2024-02
A12: 11 | B12: Joseph Moreno | C12: mbrown@example.org | D12: 48 | E12: Male | F12: Nintendo Switch | G12: 2021-01-19 | H12: Cancellation request | I12: Data loss | J12: I'm having an issue with the {product_purchased}. Please assist. 1-800-799-0808. Product Search: What's New in 2-3-4-5? Report Feedback Customer Service is your best I'm using the original charger that came with my {product_purchased}, but it's not charging properly. | K12: Closed | L12: Measure tonight surface feel forward. | M12: High | N12: Phone | O12: 2023-06-01 17:46:49 | P12: 2023-05-31 23:51:49 | Q12: 1 | R12: High | S12: Closed | T12: Billing | U12: Kevin Bacon | V12: 44584.311 | W12: 2022-01-27 12:00:37.836337328 | X12: 100.55 | Y12: 2022-01
A13: 12 | B13: Brandon Arnold | C13: davisjohn@example.net | D13: 51 | E13: Male | F13: Microsoft Xbox Controller | G13: 2021-10-24 | H13: Product inquiry | I13: Software bug | J13: I'm having an issue with the {product_purchased}. Please assist. 4. It is possible that we cannot find some type of text or a product name to identify someone like Mr. Brown. 5. On the I've reviewed the troubleshooting steps on the official support website, but they didn't resolve the problem. | K13: Closed | L13: Measure there house management pick knowledge trade. | M13: High | N13: Chat | O13: 2023-06-01 12:05:51 | P13: 2023-06-01 09:27:51 | Q13: 1 | R13: High | S13: Closed | T13: Technical | U13: Laura Croft | V13: 45623.822 | W13: 2024-11-28 13:02:27.293341875 | X13: 17.31 | Y13: 2024-11
A14: 13 | B14: Tamara Hahn | C14: jensenwilliam@example.net | D14: 27 | E14: Other | F14: Nintendo Switch Pro Controller | G14: 2021-05-26 | H14: Technical issue | I14: Hardware issue | J14: I'm having an issue with the {product_purchased}. Please assist. CQW: Why didn't I send him the invoice? Thanks a lot. L: He's like the best customer I've met. I've noticed that the issue occurs consistently when I use a specific feature or application on my {product_purchased}. | K14: Pending Customer Response | L14: Under Investigation | M14: Low | N14: Chat | O14: 2023-06-01 19:03:53 | Q14: -1 | R14: Low | S14: Pending Customer Response | T14: Billing | U14: Oliver Twist | V14: 45473.296 | Y14: 2024-06
A15: 14 | B15: Sandra Barnes | C15: gwendolyn51@example.net | D15: 65 | E15: Other | F15: Nest Thermostat | G15: 2020-07-13 | H15: Technical issue | I15: Product setup | J15: I've recently set up my {product_purchased}, but it fails to connect to any available networks. What steps should I take to troubleshoot this issue? I can't find the 'Product_IP' field of the I'm concerned about the security of my {product_purchased} and would like to ensure that my data is safe. | K15: Pending Customer Response | L15: Under Investigation | M15: Low | N15: Chat | O15: 2023-06-01 20:34:54 | Q15: -1 | R15: Low | S15: Pending Customer Response | T15: Technical | U15: Ian Malcolm | V15: 44794.282 | Y15: 2022-08
A16: 15 | B16: Amy Hill | C16: medinasteven@example.net | D16: 48 | E16: Female | F16: Sony PlayStation | G16: 2020-02-29 | H16: Billing inquiry | I16: Product setup | J16: I'm having an issue with the {product_purchased}. Please assist. Product Name: TPUBASK3E3KQ0 Join Date: Oct 2007 Posts: 11,532 Quote: I've recently updated the firmware of my {product_purchased}, and the issue started happening afterward. Could it be related to the update? | K16: Closed | L16: Officer moment world sing parent available. | M16: High | N16: Chat | O16: 2023-06-01 06:22:55 | P16: 2023-05-31 23:08:55 | Q16: 4 | R16: High | S16: Closed | T16: Shipping | U16: Bob Johnson | V16: 44760.869 | W16: 2022-07-23 05:55:48.497529268 | X16: 105.07 | Y16: 2022-07
A17: 16 | B17: Elizabeth Foley | C17: amy41@example.net | D17: 18 | E17: Other | F17: GoPro Action Camera | G17: 2021-06-24 | H17: Billing inquiry | I17: Product recommendation | J17: I'm having an issue with the {product_purchased}. Please assist. Please note, you might have already paid for this product, which means spectators are not buying any of the products from the sale as their donations will go straight I've noticed a sudden decrease in battery life on my {product_purchased}. It used to last much longer. | K17: Pending Customer Response | L17: Under Investigation | M17: High | N17: Social media | O17: 2023-06-01 15:09:57 | Q17: -1 | R17: High | S17: Pending Customer Response | T17: Technical | U17: Julia Roberts | V17: 44762.599 | Y17: 2022-07
A18: 17 | B18: Julia Salazar | C18: watkinsbarbara@example.com | D18: 63 | E18: Other | F18: Xbox | G18: 2021-10-13 | H18: Product inquiry | I18: Account access | J18: I'm having an issue with the {product_purchased}. Please assist. - Acknowledgement: Thanks to Dan for the tip. When you purchase a new product from my store or from your local retailer, they will also provide I'm concerned about the security of my {product_purchased} and would like to ensure that my data is safe. | K18: Closed | L18: Seek evidence book collection catch. | M18: Critical | N18: Chat | O18: 2023-06-01 19:46:59 | P18: 2023-06-01 15:58:59 | Q18: 4 | R18: High | S18: Closed | T18: Login | U18: George Clark | V18: 44894.916 | W18: 2022-11-30 23:50:10.121916056 | X18: 25.85 | Y18: 2022-11
A19: 18 | B19: Joshua Castillo | C19: mooredeborah@example.org | D19: 56 | E19: Female | F19: Microsoft Xbox Controller | G19: 2020-09-07 | H19: Product inquiry | I19: Payment issue | J19: I'm having an issue with the {product_purchased}. Please assist. Thanks!" * [0] - [0] - [0] - [0] If this product is sold and you have not used any I've reviewed the troubleshooting steps on the official support website, but they didn't resolve the problem. | K19: Pending Customer Response | L19: Under Investigation | M19: High | N19: Chat | O19: 2023-06-01 21:05:01 | Q19: -1 | R19: High | S19: Pending Customer Response | T19: Billing | U19: Alice Smith | V19: 45136.379 | Y19: 2023-07
A20: 19 | B20: Wendy Davis | C20: brenda20@example.net | D20: 19 | E20: Male | F20: LG Washing Machine | G20: 2021-09-23 | H20: Product inquiry | I20: Peripheral compatibility | J20: I'm having an issue with the {product_purchased}. Please assist. I want to be an active member of our community on YouTube... The issue I'm facing is intermittent. Sometimes it works fine, but other times it acts up unexpectedly. | K20: Open | L20: Under Investigation | M20: High | N20: Social media | Q20: -1 | R20: High | S20: Open | T20: Account | U20: Alice Smith | V20: 45034.751 | Y20: 2023-04
A21: 20 | B21: Jeffrey Robertson | C21: jameslopez@example.com | D21: 39 | E21: Female | F21: Canon EOS | G21: 2021-03-08 | H21: Refund request | I21: Software bug | J21: I'm having an issue with the {product_purchased}. Please assist. I'm having an issue with the product_purchased}. Please assist. Customer Reviewer: My Husband was able to take an order from Apple I've checked for any available software updates for my {product_purchased}, but there are none. | K21: Closed | L21: Wish mouth build resource though. | M21: Low | N21: Chat | O21: 2023-06-01 00:46:04 | P21: 2023-06-01 20:29:04 | Q21: 5 | R21: Low | S21: Closed | T21: Technical | U21: Bob Johnson | V21: 44880.667 | W21: 2022-11-18 03:16:18.495856285 | X21: 59.27 | Y21: 2022-11
A22: 21 | B22: Suzanne Holmes | C22: rogermcgrath@example.net | D22: 28 | E22: Other | F22: HP Pavilion | G22: 2021-05-31 | H22: Refund request | I22: Payment issue | J22: I'm having an issue with the {product_purchased}. Please assist. " -name "Microsoft Surface Pro. " " -version 1.10.2 "1.10.2" " -usage I've checked for any available software updates for my {product_purchased}, but there are none. | K22: Pending Customer Response | L22: Under Investigation | M22: High | N22: Chat | O22: 2023-06-01 05:08:05 | Q22: -1 | R22: High | S22: Pending Customer Response | T22: Billing | U22: Diana Prince | V22: 45231.75 | Y22: 2023-11
A23: 22 | B23: Tanner Conley | C23: zbond@example.net | D23: 66 | E23: Male | F23: Fitbit Versa Smartwatch | G23: 2020-02-04 | H23: Cancellation request | I23: Installation support | J23: I'm having an issue with the {product_purchased}. Please assist. The email address should change to: customer@julietr.com, as there is a unique id number unique for each product. You I've tried different settings and configurations on my {product_purchased}, but the issue persists. | K23: Pending Customer Response | L23: Under Investigation | M23: Critical | N23: Social media | O23: 2023-05-31 23:57:07 | Q23: -1 | R23: High | S23: Pending Customer Response | T23: Shipping | U23: Diana Prince | V23: 44714.517 | Y23: 2022-06
A24: 23 | B24: Stephanie Nelson DVM | C24: ljohnson@example.org | D24: 54 | E24: Female | F24: Xbox | G24: 2020-02-11 | H24: Cancellation request | I24: Delivery problem | J24: I'm having an issue with the {product_purchased}. Please assist. (And if need be this time, that could help.) 1.3.2.1 Update my version to 3.0 or more. The issue I'm facing is intermittent. Sometimes it works fine, but other times it acts up unexpectedly. | K24: Open | L24: Under Investigation | M24: Medium | N24: Social media | Q24: -1 | R24: Medium | S24: Open | T24: Shipping | U24: Ian Malcolm | V24: 44881.669 | Y24: 2022-11
A25: 24 | B25: Antonio Scott | C25: carlsonmatthew@example.org | D25: 63 | E25: Female | F25: Nintendo Switch Pro Controller | G25: 2021-08-06 | H25: Technical issue | I25: Refund request | J25: I'm having an issue with the {product_purchased}. Please assist. I'll take care of those. I've performed a factory reset on my {product_purchased}, hoping it would resolve the problem, but it didn't help. | K25: Pending Customer Response | L25: Under Investigation | M25: Low | N25: Social media | O25: 2023-06-01 09:06:09 | Q25: -1 | R25: Low | S25: Pending Customer Response | T25: Refund | U25: Julia Roberts | V25: 44962.937 | Y25: 2023-02
A26: 25 | B26: John Cuevas | C26: lbarron@example.org | D26: 19 | E26: Male | F26: Amazon Kindle | G26: 2021-05-25 | H26: Product inquiry | I26: Display issue | J26: I'm having an issue with the {product_purchased}. Please assist. {product_purchased} does not represent the price which you received by the day immediately before the shipment date. In many cases, this is the I've noticed a sudden decrease in battery life on my {product_purchased}. It used to last much longer. | K26: Open | L26: Under Investigation | M26: Critical | N26: Email | Q26: -1 | R26: High | S26: Open | T26: Billing | U26: Alice Smith | V26: 45061.167 | Y26: 2023-05
A27: 26 | B27: Gregory Bautista | C27: johnstonbeth@example.com | D27: 35 | E27: Other | F27: HP Pavilion | G27: 2021-07-05 | H27: Product inquiry | I27: Refund request | J27: My {product_purchased} is making strange noises and not functioning properly. I suspect there might be a hardware issue. Can you please help me with this? Thank you, Thank you for posting. It took me a I'm experiencing this issue on multiple devices of the same model, so it seems to be a widespread problem. | K27: Pending Customer Response | L27: Under Investigation | M27: Medium | N27: Social media | O27: 2023-06-01 19:02:12 | Q27: -1 | R27: Medium | S27: Pending Customer Response | T27: Refund | U27: Ian Malcolm | V27: 45421.539 | Y27: 2024-05
A28: 27 | B28: Ryan Sharp | C28: pmercado@example.org | D28: 22 | E28: Other | F28: Lenovo ThinkPad | G28: 2020-05-02 | H28: Billing inquiry | I28: Cancellation request | J28: I'm encountering a software bug in the {product_purchased}. Whenever I try to perform a specific action, the application crashes. Are there any updates or fixes available? On Windows Vista, this is not possible. If you are I've performed a factory reset on my {product_purchased}, hoping it would resolve the problem, but it didn't help. | K28: Pending Customer Response | L28: Under Investigation | M28: Low | N28: Social media | O28: 2023-06-01 20:02:13 | Q28: -1 | R28: Low | S28: Pending Customer Response | T28: Login | U28: Diana Prince | V28: 44780.414 | Y28: 2022-08
A29: 28 | B29: Michael Mcdowell | C29: jeffersonmichael@example.net | D29: 21 | E29: Other | F29: Fitbit Charge | G29: 2020-10-12 | H29: Cancellation request | I29: Product setup | J29: I'm having an issue with the {product_purchased}. Please assist. {{product_purchased}} must be a valid email address for your order and are valid for one week in advance. Please make your purchases as quickly as possible The issue I'm facing is intermittent. Sometimes it works fine, but other times it acts up unexpectedly. | K29: Open | L29: Under Investigation | M29: High | N29: Phone | Q29: -1 | R29: High | S29: Open | T29: Shipping | U29: Laura Croft | V29: 45124.858 | Y29: 2023-07
A30: 29 | B30: Christine Wang | C30: garciastacy@example.com | D30: 30 | E30: Other | F30: Fitbit Charge | G30: 2020-06-10 | H30: Technical issue | I30: Product recommendation | J30: I'm having an issue with the {product_purchased}. Please assist. Thank you." A statement from the consumer group had been released by Microsoft late on Tuesday afternoon. "The purchase of this product was made using a contract with I'm using the original charger that came with my {product_purchased}, but it's not charging properly. | K30: Closed | L30: Soldier we such inside. | M30: Critical | N30: Phone | O30: 2023-05-31 23:17:17 | P30: 2023-06-01 06:03:17 | Q30: 5 | R30: High | S30: Closed | T30: Billing | U30: Kevin Bacon | V30: 45210.465 | W30: 2023-10-12 00:48:17.530900002 | X30: 13.65 | Y30: 2023-10
A31: 30 | B31: Austin George | C31: shericase@example.net | D31: 67 | E31: Male | F31: Xbox | G31: 2020-12-26 | H31: Cancellation request | I31: Cancellation request | J31: I'm having an issue with the {product_purchased}. Please assist. It's not possible to remove the missing content. I've already contacted customer support multiple times, but the issue remains unresolved. | K31: Closed | L31: Firm sort voice above which site arrive. | M31: Medium | N31: Phone | O31: 2023-06-01 00:54:17 | P31: 2023-06-01 18:23:17 | Q31: 1 | R31: Medium | S31: Closed | T31: Technical | U31: Laura Croft | V31: 44612.634 | W31: 2022-02-23 12:35:48.646613598 | X31: 69.38 | Y31: 2022-02
A32: 31 | B32: Wendy Roberts | C32: jessicahenderson@example.net | D32: 22 | E32: Other | F32: Adobe Photoshop | G32: 2021-01-28 | H32: Billing inquiry | I32: Product setup | J32: I'm having an issue with the {product_purchased}. Please assist. I'm using a brand new product. What a strange situation. I've just purchased a brand new one. What to do? I've noticed that the issue occurs consistently when I use a specific feature or application on my {product_purchased}. | K32: Open | L32: Under Investigation | M32: Low | N32: Email | Q32: -1 | R32: Low | S32: Open | T32: Technical | U32: Ian Malcolm | V32: 45227.032 | Y32: 2023-10
A33: 32 | B33: Robert Wilson | C33: zstewart@example.org | D33: 60 | E33: Male | F33: GoPro Action Camera | G33: 2021-12-20 | H33: Technical issue | I33: Product compatibility | J33: I'm having an issue with the {product_purchased}. Please assist. The seller has sold the item for $29.89. When we receive your replacement, we will exchange the item for a full refund or exchange immediately upon I've already contacted customer support multiple times, but the issue remains unresolved. | K33: Closed | L33: Certain myself month past tree benefit. | M33: Medium | N33: Social media | O33: 2023-06-01 06:42:21 | P33: 2023-06-01 07:16:21 | Q33: 3 | R33: Medium | S33: Closed | T33: Refund | U33: George Clark | V33: 44748.495 | W33: 2022-07-10 16:33:14.293807268 | X33: 100.68 | Y33: 2022-07
A34: 33 | B34: Christina Gray | C34: greenkeith@example.net | D34: 36 | E34: Female | F34: Fitbit Charge | G34: 2021-12-07 | H34: Billing inquiry | I34: Product recommendation | J34: I've noticed a software bug in the {product_purchased} app. It's causing data loss and unexpected errors. How can I resolve this issue? I need assistance as soon as possible because it's affecting my work and productivity. | K34: Pending Customer Response | L34: Under Investigation | M34: Medium | N34: Chat | O34: 2023-06-01 19:36:21 | Q34: -1 | R34: Medium | S34: Pending Customer Response | T34: Technical | U34: Diana Prince | V34: 44633.002 | Y34: 2022-03
A35: 34 | B35: Timothy Lyons | C35: darlenelee@example.org | D35: 50 | E35: Male | F35: Autodesk AutoCAD | G35: 2021-12-09 | H35: Refund request | I35: Hardware issue | J35: I'm having an issue with the {product_purchased}. Please assist. We hope that every vendor takes the time it takes in to do the following: "Remove the product from your account - notify consumers, call them, make their I'm concerned about the security of my {product_purchased} and would like to ensure that my data is safe. | K35: Closed | L35: However financial development significant camera job every. | M35: Critical | N35: Social media | O35: 2023-06-01 02:01:23 | P35: 2023-06-01 18:25:23 | Q35: 5 | R35: High | S35: Closed | T35: Account | U35: Hannah Abbott | V35: 45600.8 | W35: 2024-11-08 02:50:30.908463478 | X35: 79.63 | Y35: 2024-11
A36: 35 | B36: Stacy Jones | C36: fernandezmark@example.org | D36: 27 | E36: Male | F36: Microsoft Xbox Controller | G36: 2021-04-09 | H36: Refund request | I36: Installation support | J36: I'm having an issue with the {product_purchased}. Please assist. 3-3 We are in, the first day, at the {product_purchased}. Please assist. 3-2 Please assist us I've recently updated the firmware of my {product_purchased}, and the issue started happening afterward. Could it be related to the update? | K36: Pending Customer Response | L36: Under Investigation | M36: Low | N36: Chat | O36: 2023-06-01 20:50:24 | Q36: -1 | R36: Low | S36: Pending Customer Response | T36: Technical | U36: Julia Roberts | V36: 45619.138 | Y36: 2024-11
A37: 36 | B37: Joann King | C37: jessica10@example.org | D37: 24 | E37: Other | F37: GoPro Hero | G37: 2020-10-13 | H37: Cancellation request | I37: Product recommendation | J37: I've recently set up my {product_purchased}, but it fails to connect to any available networks. What steps should I take to troubleshoot this issue? If you know the answer, please let me know. Do I I've noticed a sudden decrease in battery life on my {product_purchased}. It used to last much longer. | K37: Closed | L37: Reach paper ability effort learn. | M37: High | N37: Chat | O37: 2023-06-01 07:56:25 | P37: 2023-06-01 00:14:25 | Q37: 1 | R37: High | S37: Closed | T37: Technical | U37: Ethan Hunt | V37: 45446.966 | W37: 2024-06-06 15:13:56.310602188 | X37: 64.05 | Y37: 2024-06
A38: 37 | B38: Ruben Henry | C38: katherinehoward@example.net | D38: 65 | E38: Female | F38: Canon EOS | G38: 2020-03-14 | H38: Refund request | I38: Hardware issue | J38: I'm having an issue with the {product_purchased}. Please assist. I have to ask for support from you, the customers, before the item's arrival and I can't do that. In the short term, will you pay me I've followed the troubleshooting steps mentioned in the user manual, but the issue persists. | K38: Pending Customer Response | L38: Under Investigation | M38: Medium | N38: Email | O38: 2023-06-01 15:51:28 | Q38: -1 | R38: Medium | S38: Pending Customer Response | T38: Technical | U38: Michael Scott | V38: 44895.323 | Y38: 2022-11
A39: 38 | B39: Morgan Wagner | C39: elizabethlamb@example.com | D39: 39 | E39: Female | F39: Amazon Kindle | G39: 2020-09-02 | H39: Product inquiry | I39: Product compatibility | J39: I've forgotten my password for my {product_purchased} account, and the password reset option is not working. How can I recover my account? I can reset my password by entering the following: My password still valid: password is expired I've recently updated the firmware of my {product_purchased}, and the issue started happening afterward. Could it be related to the update? | K39: Open | L39: Under Investigation | M39: Medium | N39: Chat | Q39: -1 | R39: Medium | S39: Open | T39: Login | U39: Nancy Drew | V39: 44668.722 | Y39: 2022-04
A40: 39 | B40: Kevin Ingram | C40: victor62@example.net | D40: 19 | E40: Male | F40: Google Pixel | G40: 2021-09-10 | H40: Technical issue | I40: Account access | J40: I'm having an issue with the {product_purchased}. Please assist. 1. Do I need to purchase a refund? There is a way to purchase a refund from ZEROHITS, but there's not a I'm unable to find the option to perform the desired action in the {product_purchased}. Could you please guide me through the steps? | K40: Closed | L40: North second between this cell opportunity movement. | M40: Critical | N40: Phone | O40: 2023-06-01 18:45:30 | P40: 2023-05-31 21:53:30 | Q40: 3 | R40: High | S40: Closed | T40: Refund | U40: Alice Smith | V40: 45311.006 | W40: 2024-01-23 12:54:14.172262192 | X40: 84.76 | Y40: 2024-01
...
